<?xml version="1.0" encoding="utf-8"?>
<!-- =================================================================================== -->
<!-- |    This document was autogenerated by xacro from /home/ros/wheelchair/src/mdu_description/urdf/mdu.xacro | -->
<!-- |    EDITING THIS FILE BY HAND IS NOT RECOMMENDED                                 | -->
<!-- =================================================================================== -->
<robot name="mdu" xmlns:xacro="http://www.ros.org/wiki/xacro">
  <gazebo>
    <plugin filename="libgazebo_ros_diff_drive.so" name="differential_drive_controller">
      <legacyMode>false</legacyMode>
      <alwaysOn>true</alwaysOn>
      <updateRate>20</updateRate>
      <leftJoint>axle_rear_left_wheel_joint</leftJoint>
      <rightJoint>axle_rear_right_wheel_joint</rightJoint>
      <wheelSeparation>0.32</wheelSeparation>
      <wheelDiameter>0.254</wheelDiameter>
      <torque>20</torque>
      <commandTopic>cmd_vel</commandTopic>
      <odometryTopic>odom</odometryTopic>
      <odometryFrame>odom</odometryFrame>
      <robotBaseFrame>footprint</robotBaseFrame>
    </plugin>
  </gazebo>
  <gazebo reference="footprint">
    <material>Gazebo/Red</material>
  </gazebo>
  <gazebo reference="rear_right_wheel">
    <material>Gazebo/Black</material>
    <mu1 value="200.0"/>
    <mu2 value="100.0"/>
    <kp value="10000000.0"/>
    <kd value="1.0"/>
  </gazebo>
  <gazebo reference="rear_left_wheel">
    <material>Gazebo/Black</material>
    <mu1 value="200.0"/>
    <mu2 value="100.0"/>
    <kp value="10000000.0"/>
    <kd value="1.0"/>
    <fdir1 value="1 0 0"/>
  </gazebo>
  <material name="black">
    <color rgba="0.0 0.0 0.0 1.0"/>
  </material>
  <material name="blue">
    <color rgba="0.0 0.0 0.8 1.0"/>
  </material>
  <material name="green">
    <color rgba="0.0 0.8 0.0 1.0"/>
  </material>
  <material name="grey">
    <color rgba="0.2 0.2 0.2 1.0"/>
  </material>
  <material name="orange">
    <color rgba="1.0 0.423529411765 0.0392156862745 1.0"/>
  </material>
  <material name="brown">
    <color rgba="0.870588235294 0.811764705882 0.764705882353 1.0"/>
  </material>
  <material name="red">
    <color rgba="0.8 0.0 0.0 1.0"/>
  </material>
  <material name="white">
    <color rgba="1.0 1.0 1.0 1.0"/>
  </material>
  <link name="footprint">
    <pose rpy=" 0 0 0" xyz="-10 0 0"/>
    <visual>
      <origin rpy=" 0 0 0" xyz="0 0 0"/>
      <geometry>
        <box size="0.001 0.001 0.001"/>
      </geometry>
    </visual>
    <!--visual>
      <origin xyz="0 0 0" rpy="0 0 -3.14"/>
      <geometry>
         <mesh filename="package://wheelchair_description/meshes/wheelchair_chasis.stl" scale="0.01 0.01 0.01"/>
      </geometry>
  </visual-->
  </link>
  <link name="axle">
    <inertial>
      <origin rpy=" 0 0 0" xyz="0 0 0"/>
      <mass value="2.0"/>
      <inertia ixx="0.0170833333333" ixy="0" ixz="0" iyy="3.33333333333e-05" iyz="0" izz="3.33333333333e-05"/>
    </inertial>
    <collision name="collision">
      <origin rpy=" 0 0 0" xyz="0 0 0"/>
      <geometry>
        <box size="0.01 0.32 0.01"/>
      </geometry>
    </collision>
    <visual>
      <origin rpy=" 0 0 0" xyz="0 0 0"/>
      <geometry>
        <box size="0.01 0.32 0.01"/>
      </geometry>
    </visual>
  </link>
  <link name="caster">
    <collision name="caster_collision">
      <origin rpy=" 0 0 0" xyz="0 0 0"/>
      <geometry>
        <sphere radius="0.0635"/>
      </geometry>
      <surface>
        <friction>
          <ode>
            <mu>0</mu>
            <mu2>0</mu2>
            <slip1>1.0</slip1>
            <slip2>1.0</slip2>
          </ode>
        </friction>
      </surface>
    </collision>
    <visual name="caster_visual">
      <origin rpy=" 0 0 0" xyz="0 0 0"/>
      <geometry>
        <sphere radius="0.0635"/>
      </geometry>
    </visual>
  </link>
  <joint name="footprint_axle_joint" type="fixed">
    <origin rpy="0 0 0" xyz="0 0 0.127"/>
    <parent link="footprint"/>
    <child link="axle"/>
  </joint>
  <link name="base">
    <collision name="base_chassis_collision">
      <geometry>
        <box size="0.2 0.3 0.22"/>
      </geometry>
    </collision>
    <visual name="base_visual">
      <origin rpy="0 0 0" xyz="0.1 0 0"/>
      <geometry>
        <box size="0.2 0.3 0.22"/>
      </geometry>
    </visual>
    <inertial name="base_intertial">
      <origin rpy="0 0 0" xyz="0.1 0 0"/>
      <mass value="10.0"/>
      <inertia ixx="0.115333333333" ixy="0" ixz="0" iyy="0.0736666666667" iyz="0" izz="0.0736666666667"/>
    </inertial>
  </link>
  <joint name="axle_base_joint" type="fixed">
    <origin rpy="0 0 0" xyz="0 0 0"/>
    <parent link="axle"/>
    <child link="base"/>
  </joint>
  <joint name="base_caster_joint" type="fixed">
    <origin rpy="0 0 0" xyz="0.1365 0 -0.0635"/>
    <parent link="base"/>
    <child link="caster"/>
  </joint>
  <link name="rear_left_wheel">
    <collision name="rear_left_wheel_collision">
      <origin rpy="-1.57079632679 0 0" xyz=" 0 0 0"/>
      <geometry>
        <cylinder length="0.05" radius="0.127"/>
      </geometry>
    </collision>
    <visual name="rear_left_wheel_visual">
      <transparency>0.1</transparency>
      <origin rpy="-1.57079632679 0 0" xyz=" 0 0 0"/>
      <geometry>
        <cylinder length="0.03" radius="0.127"/>
      </geometry>
      <material name="green"/>
    </visual>
    <!--visual name="${lr}_visual_mesh">
        <origin xyz="${xyz}" rpy="${rpy}" />

        <geometry>
          <mesh filename="package://wheelchair_description/meshes/${meshFile}.stl" scale="0.01 0.01 0.01"/>
        </geometry>
      </visual-->
    <inertial name="rear_left_wheel_visual_intertial">
      <origin rpy="0 1.57079632679 1.57079632679" xyz="0 0 0"/>
      <mass value="3.0"/>
      <inertia ixx="0.01272175" ixy="0" ixz="0" iyy="0.01272175" iyz="0" izz="0.0241935"/>
    </inertial>
    <!-- This block connects the wheel joint to an actuator (motor), which informs both
		simulation and visualization of the robot -->
    <!--transmission name="${lr}_wheel_trans">
		  <type>transmission_interface/SimpleTransmission</type>
		  <actuator name="${lr}_wheel_motor">
			<mechanicalReduction>1</mechanicalReduction>
		  </actuator>
		  <joint name="${lr}_motor_wheel_joint">
			<hardwareInterface>VelocityJointInterface</hardwareInterface>
		  </joint>
		</transmission-->
  </link>
  <joint name="axle_rear_left_wheel_joint" type="continuous">
    <origin rpy="0 0 0" xyz="0 0.16 0"/>
    <child link="rear_left_wheel"/>
    <parent link="axle"/>
    <axis rpy="0 0 0" xyz="0 1 0"/>
    <limit effort="100" velocity="100"/>
    <joint_properties damping="0.01" friction="0.5"/>
  </joint>
  <link name="rear_right_wheel">
    <collision name="rear_right_wheel_collision">
      <origin rpy="1.57079632679 0 0" xyz=" 0 0 0"/>
      <geometry>
        <cylinder length="0.05" radius="0.127"/>
      </geometry>
    </collision>
    <visual name="rear_right_wheel_visual">
      <transparency>0.1</transparency>
      <origin rpy="1.57079632679 0 0" xyz=" 0 0 0"/>
      <geometry>
        <cylinder length="0.03" radius="0.127"/>
      </geometry>
      <material name="green"/>
    </visual>
    <!--visual name="${lr}_visual_mesh">
        <origin xyz="${xyz}" rpy="${rpy}" />

        <geometry>
          <mesh filename="package://wheelchair_description/meshes/${meshFile}.stl" scale="0.01 0.01 0.01"/>
        </geometry>
      </visual-->
    <inertial name="rear_right_wheel_visual_intertial">
      <origin rpy="0 1.57079632679 1.57079632679" xyz="0 0 0"/>
      <mass value="3.0"/>
      <inertia ixx="0.01272175" ixy="0" ixz="0" iyy="0.01272175" iyz="0" izz="0.0241935"/>
    </inertial>
    <!-- This block connects the wheel joint to an actuator (motor), which informs both
		simulation and visualization of the robot -->
    <!--transmission name="${lr}_wheel_trans">
		  <type>transmission_interface/SimpleTransmission</type>
		  <actuator name="${lr}_wheel_motor">
			<mechanicalReduction>1</mechanicalReduction>
		  </actuator>
		  <joint name="${lr}_motor_wheel_joint">
			<hardwareInterface>VelocityJointInterface</hardwareInterface>
		  </joint>
		</transmission-->
  </link>
  <joint name="axle_rear_right_wheel_joint" type="continuous">
    <origin rpy="0 0 0" xyz="0 -0.16 0"/>
    <child link="rear_right_wheel"/>
    <parent link="axle"/>
    <axis rpy="0 0 0" xyz="0 1 0"/>
    <limit effort="100" velocity="100"/>
    <joint_properties damping="0.01" friction="0.5"/>
  </joint>
</robot>
