<?xml version="1.0" encoding="utf-8"?>
<!-- =================================================================================== -->
<!-- |    This document was autogenerated by xacro from /home/kundan/wheelchair_ws/src/wheelchair_description/urdf/wheelchair.xacro | -->
<!-- |    EDITING THIS FILE BY HAND IS NOT RECOMMENDED                                 | -->
<!-- =================================================================================== -->
<robot name="wheelchair" xmlns:xacro="http://www.ros.org/wiki/xacro">
  <gazebo>
    <plugin filename="libgazebo_ros_diff_drive.so" name="differential_drive_controller">
      <legacyMode>false</legacyMode>
      <alwaysOn>true</alwaysOn>
      <updateRate>20</updateRate>
      <leftJoint>axel_l_joint</leftJoint>
      <rightJoint>axel_r_joint</rightJoint>
      <wheelSeparation>0.4</wheelSeparation>
      <wheelDiameter>0.4</wheelDiameter>
      <torque>20</torque>
      <commandTopic>cmd_vel</commandTopic>
      <odometryTopic>odom</odometryTopic>
      <odometryFrame>odom</odometryFrame>
      <robotBaseFrame>footprint</robotBaseFrame>
    </plugin>
  </gazebo>
  <gazebo reference="footprint">
    <material>Gazebo/Green</material>
  </gazebo>
  <material name="black">
    <color rgba="0.0 0.0 0.0 1.0"/>
  </material>
  <material name="blue">
    <color rgba="0.0 0.0 0.8 1.0"/>
  </material>
  <material name="green">
    <color rgba="0.0 0.8 0.0 1.0"/>
  </material>
  <material name="grey">
    <color rgba="0.2 0.2 0.2 1.0"/>
  </material>
  <material name="orange">
    <color rgba="1.0 0.423529411765 0.0392156862745 1.0"/>
  </material>
  <material name="brown">
    <color rgba="0.870588235294 0.811764705882 0.764705882353 1.0"/>
  </material>
  <material name="red">
    <color rgba="0.8 0.0 0.0 1.0"/>
  </material>
  <material name="white">
    <color rgba="1.0 1.0 1.0 1.0"/>
  </material>
  <!--
    <gazebo reference="${lr}_wheel">
      <mu1 value="1.0"/>
      <mu2 value="1.0"/>
      <kp  value="10000000.0" />
      <kd  value="1.0" />
      <fdir1 value="1 0 0"/>
      <material>Gazebo/Black</material>
    </gazebo>


    <joint name="${lr}_wheel_hinge" type="continuous">
      <parent link="chassis"/>
      <child link="${lr}_wheel"/>
    <origin xyz="${-wheelPos+chassisLength/2} ${tY*wheelWidth/2+tY*chassisWidth/2} ${wheelRadius}" rpy="0 0 0" />
      <axis xyz="0 1 0" rpy="0 0 0" />
      <limit effort="10000" velocity="10000"/>
      <joint_properties damping="0.0" friction="0.0"/>
    </joint>


    <transmission name="${lr}_trans">
      <type>transmission_interface/SimpleTransmission</type>
      <joint name="${lr}_wheel_hinge">
        <hardwareInterface>EffortJointInterface</hardwareInterface>
      </joint>
      <actuator name="${lr}Motor">
        <hardwareInterface>EffortJointInterface</hardwareInterface>
        <mechanicalReduction>10</mechanicalReduction>
      </actuator>
    </transmission>
  -->
  <link name="footprint">
    <visual>
      <origin rpy=" 0 0 0" xyz="0 0 0"/>
      <geometry>
        <box size="0.001 0.001 0.001"/>
      </geometry>
    </visual>
    <visual>
      <origin rpy="0 0 -3.14" xyz="0 0 0"/>
      <geometry>
        <mesh filename="package://wheelchair_description/meshes/wheelchair_chasis.stl" scale="0.01 0.01 0.01"/>
      </geometry>
    </visual>
  </link>
  <link name="axel">
    <inertial>
      <origin rpy=" 0 0 0" xyz="0 0 0"/>
      <mass value="50.0"/>
      <inertia ixx="0.687416045483" ixy="0" ixz="0" iyy="0.000833333333333" iyz="0" izz="0.000833333333333"/>
    </inertial>
    <collision name="collision">
      <origin rpy=" 0 0 0" xyz="0 0 0}"/>
      <geometry>
        <box size="0.01 0.406054 0.01"/>
      </geometry>
    </collision>
    <visual>
      <origin rpy=" 0 0 0" xyz="0 0 0"/>
      <geometry>
        <box size="0.01 0.406054 0.01"/>
      </geometry>
    </visual>
  </link>
  <joint name="footprint_axel_joint" type="fixed">
    <origin rpy="0 0 0" xyz="0 0 0.201784"/>
    <parent link="footprint"/>
    <child link="axel"/>
  </joint>
  <link name="base">
    <collision name="base_chassis_collision">
      <geometry>
        <box size="0.302676 0.203568 0.01"/>
      </geometry>
    </collision>
    <visual name="base_visual">
      <origin rpy="0 0 0" xyz="0.151338 0 0"/>
      <geometry>
        <box size="0.302676 0.203568 0.01"/>
      </geometry>
    </visual>
    <inertial name="base_intertial">
      <origin rpy="0 0 0" xyz="0.151338 0 0"/>
      <mass value="50.0"/>
      <inertia ixx="0.173083044267" ixy="0" ixz="0" iyy="0.382136504067" iyz="0" izz="0.382136504067"/>
    </inertial>
  </link>
  <joint name="axel_base_joint" type="fixed">
    <origin rpy="0 0 0" xyz="0 0 0"/>
    <parent link="axel"/>
    <child link="base"/>
  </joint>
  <link name="left_leg">
    <collision name="left_leg_chassis_collision">
      <geometry>
        <box size="0.01 0.01 0.0354"/>
      </geometry>
    </collision>
    <visual name="left_leg_visual">
      <origin rpy="0 0 0" xyz="0 0 -0.0177"/>
      <geometry>
        <box size="0.01 0.01 0.0354"/>
      </geometry>
    </visual>
    <inertial name="left_leg_intertial">
      <origin rpy="0 0 0" xyz="0 0 -0.0177"/>
      <mass value="0.1"/>
      <inertia ixx="1.12763333333e-05" ixy="0" ixz="0" iyy="1.12763333333e-05" iyz="0" izz="1.12763333333e-05"/>
    </inertial>
  </link>
  <joint name="base_left_leg_joint" type="fixed">
    <origin rpy="0 0 0" xyz="0.302676 0.101784 0"/>
    <parent link="base"/>
    <child link="left_leg"/>
  </joint>
  <link name="right_leg">
    <collision name="right_leg_chassis_collision">
      <geometry>
        <box size="0.01 0.01 0.0354"/>
      </geometry>
    </collision>
    <visual name="right_leg_visual">
      <origin rpy="0 0 0" xyz="0 0 -0.0177"/>
      <geometry>
        <box size="0.01 0.01 0.0354"/>
      </geometry>
    </visual>
    <inertial name="right_leg_intertial">
      <origin rpy="0 0 0" xyz="0 0 -0.0177"/>
      <mass value="0.1"/>
      <inertia ixx="1.12763333333e-05" ixy="0" ixz="0" iyy="1.12763333333e-05" iyz="0" izz="1.12763333333e-05"/>
    </inertial>
  </link>
  <joint name="base_right_leg_joint" type="fixed">
    <origin rpy="0 0 0" xyz="0.302676 -0.101784 0"/>
    <parent link="base"/>
    <child link="right_leg"/>
  </joint>
  <link name="l_rev">
    <collision name="l_rev_collision">
      <origin rpy="0 0 0" xyz=" 0 0 0"/>
      <geometry>
        <cylinder length="0.0356884" radius="0.01"/>
      </geometry>
    </collision>
    <!--
      <visual name="${lr}_visual">
        <transparency>0.1</transparency>
        <origin xyz="${xyz}" rpy="${rpy}" />
        <geometry>
          <cylinder length="${wheelWidth - tY}" radius="${wheelRadius}"/>
        </geometry>

        <material name="green"/>
      </visual>
    -->
    <visual name="l_rev_visual_mesh">
      <origin rpy="0 0 0" xyz=" 0 0 0"/>
      <geometry>
        <mesh filename="package://wheelchair_description/meshes/wheelchair_wheel_rev.stl" scale="0.01 0.01 0.01"/>
      </geometry>
    </visual>
    <inertial name="l_rev_visual_intertial">
      <origin rpy="0 1.57079632679 1.57079632679" xyz="0 0 0"/>
      <mass value="0.1"/>
      <inertia ixx="1.31138491213e-05" ixy="0" ixz="0" iyy="1.31138491213e-05" iyz="0" izz="5e-06"/>
    </inertial>
  </link>
  <joint name="left_leg_l_rev_joint" type="continuous">
    <origin rpy="0 0 0" xyz="0 0 -0.0354"/>
    <child link="l_rev"/>
    <parent link="left_leg"/>
    <axis rpy="0 0 0" xyz="0 0 1"/>
    <limit effort="100" velocity="100"/>
    <joint_properties damping="0.0" friction="0.0"/>
  </joint>
  <link name="left_leg_b">
    <collision name="left_leg_b_chassis_collision">
      <geometry>
        <box size="0.01 0.01 0.1065"/>
      </geometry>
    </collision>
    <visual name="left_leg_b_visual">
      <origin rpy="0 0 0" xyz="0 0 -0.05325"/>
      <geometry>
        <box size="0.01 0.01 0.1065"/>
      </geometry>
    </visual>
    <inertial name="left_leg_b_intertial">
      <origin rpy="0 0 0" xyz="0 0 -0.05325"/>
      <mass value="0.1"/>
      <inertia ixx="9.53520833333e-05" ixy="0" ixz="0" iyy="9.53520833333e-05" iyz="0" izz="9.53520833333e-05"/>
    </inertial>
  </link>
  <joint name="l_rev_left_leg_b_joint" type="fixed">
    <origin rpy="0 0 0" xyz="0 0 0"/>
    <parent link="l_rev"/>
    <child link="left_leg_b"/>
  </joint>
  <link name="r_rev">
    <collision name="r_rev_collision">
      <origin rpy="0 0 0" xyz=" 0 0 0"/>
      <geometry>
        <cylinder length="0.0356884" radius="0.01"/>
      </geometry>
    </collision>
    <!--
      <visual name="${lr}_visual">
        <transparency>0.1</transparency>
        <origin xyz="${xyz}" rpy="${rpy}" />
        <geometry>
          <cylinder length="${wheelWidth - tY}" radius="${wheelRadius}"/>
        </geometry>

        <material name="green"/>
      </visual>
    -->
    <visual name="r_rev_visual_mesh">
      <origin rpy="0 0 0" xyz=" 0 0 0"/>
      <geometry>
        <mesh filename="package://wheelchair_description/meshes/wheelchair_wheel_rev.stl" scale="0.01 0.01 0.01"/>
      </geometry>
    </visual>
    <inertial name="r_rev_visual_intertial">
      <origin rpy="0 1.57079632679 1.57079632679" xyz="0 0 0"/>
      <mass value="0.1"/>
      <inertia ixx="1.31138491213e-05" ixy="0" ixz="0" iyy="1.31138491213e-05" iyz="0" izz="5e-06"/>
    </inertial>
  </link>
  <joint name="right_leg_r_rev_joint" type="continuous">
    <origin rpy="0 0 0" xyz="0 0 -0.0354"/>
    <child link="r_rev"/>
    <parent link="right_leg"/>
    <axis rpy="0 0 0" xyz="0 0 1"/>
    <limit effort="100" velocity="100"/>
    <joint_properties damping="0.0" friction="0.0"/>
  </joint>
  <link name="right_leg_b">
    <collision name="right_leg_b_chassis_collision">
      <geometry>
        <box size="0.01 0.01 0.1065"/>
      </geometry>
    </collision>
    <visual name="right_leg_b_visual">
      <origin rpy="0 0 0" xyz="0 0 -0.05325"/>
      <geometry>
        <box size="0.01 0.01 0.1065"/>
      </geometry>
    </visual>
    <inertial name="right_leg_b_intertial">
      <origin rpy="0 0 0" xyz="0 0 -0.05325"/>
      <mass value="0.1"/>
      <inertia ixx="9.53520833333e-05" ixy="0" ixz="0" iyy="9.53520833333e-05" iyz="0" izz="9.53520833333e-05"/>
    </inertial>
  </link>
  <joint name="r_rev_right_leg_b_joint" type="fixed">
    <origin rpy="0 0 0" xyz="0 0 0"/>
    <parent link="r_rev"/>
    <child link="right_leg_b"/>
  </joint>
  <link name="l">
    <collision name="l_collision">
      <origin rpy="-1.57079632679 0 0" xyz=" 0 0 0"/>
      <geometry>
        <cylinder length="0.0356884" radius="0.201784"/>
      </geometry>
    </collision>
    <!--
      <visual name="${lr}_visual">
        <transparency>0.1</transparency>
        <origin xyz="${xyz}" rpy="${rpy}" />
        <geometry>
          <cylinder length="${wheelWidth - tY}" radius="${wheelRadius}"/>
        </geometry>

        <material name="green"/>
      </visual>
    -->
    <visual name="l_visual_mesh">
      <origin rpy="-1.57079632679 0 0" xyz=" 0 0 0"/>
      <geometry>
        <mesh filename="package://wheelchair_description/meshes/wheelchair_wheel.stl" scale="0.01 0.01 0.01"/>
      </geometry>
    </visual>
    <inertial name="l_visual_intertial">
      <origin rpy="0 1.57079632679 1.57079632679" xyz="0 0 0"/>
      <mass value="3.0"/>
      <inertia ixx="0.0308560024656" ixy="0" ixz="0" iyy="0.0308560024656" iyz="0" izz="0.061075173984"/>
    </inertial>
  </link>
  <joint name="axel_l_joint" type="continuous">
    <origin rpy="0 0 0" xyz="0 0.201784 0"/>
    <child link="l"/>
    <parent link="axel"/>
    <axis rpy="0 0 0" xyz="0 1 0"/>
    <limit effort="100" velocity="100"/>
    <joint_properties damping="0.0" friction="0.0"/>
  </joint>
  <link name="r">
    <collision name="r_collision">
      <origin rpy="1.57079632679 0 0" xyz=" 0 0 0"/>
      <geometry>
        <cylinder length="0.0356884" radius="0.201784"/>
      </geometry>
    </collision>
    <!--
      <visual name="${lr}_visual">
        <transparency>0.1</transparency>
        <origin xyz="${xyz}" rpy="${rpy}" />
        <geometry>
          <cylinder length="${wheelWidth - tY}" radius="${wheelRadius}"/>
        </geometry>

        <material name="green"/>
      </visual>
    -->
    <visual name="r_visual_mesh">
      <origin rpy="1.57079632679 0 0" xyz=" 0 0 0"/>
      <geometry>
        <mesh filename="package://wheelchair_description/meshes/wheelchair_wheel.stl" scale="0.01 0.01 0.01"/>
      </geometry>
    </visual>
    <inertial name="r_visual_intertial">
      <origin rpy="0 1.57079632679 1.57079632679" xyz="0 0 0"/>
      <mass value="3.0"/>
      <inertia ixx="0.0308560024656" ixy="0" ixz="0" iyy="0.0308560024656" iyz="0" izz="0.061075173984"/>
    </inertial>
  </link>
  <joint name="axel_r_joint" type="continuous">
    <origin rpy="0 0 0" xyz="0 -0.201784 0"/>
    <child link="r"/>
    <parent link="axel"/>
    <axis rpy="0 0 0" xyz="0 1 0"/>
    <limit effort="100" velocity="100"/>
    <joint_properties damping="0.0" friction="0.0"/>
  </joint>
  <link name="lf">
    <collision name="lf_collision">
      <origin rpy="1.57079632679 0 0" xyz=" 0 0 0"/>
      <geometry>
        <cylinder length="0.032" radius="0.068"/>
      </geometry>
    </collision>
    <!--
      <visual name="${lr}_visual">
        <transparency>0.1</transparency>
        <origin xyz="${xyz}" rpy="${rpy}" />
        <geometry>
          <cylinder length="${wheelWidth - tY}" radius="${wheelRadius}"/>
        </geometry>

        <material name="green"/>
      </visual>
    -->
    <visual name="lf_visual_mesh">
      <origin rpy="1.57079632679 0 0" xyz=" 0 0 0"/>
      <geometry>
        <mesh filename="package://wheelchair_description/meshes/wheelchair_wheel_small.stl" scale="0.01 0.01 0.01"/>
      </geometry>
    </visual>
    <inertial name="lf_visual_intertial">
      <origin rpy="0 1.57079632679 1.57079632679" xyz="0 0 0"/>
      <mass value="1.0"/>
      <inertia ixx="0.00124133333333" ixy="0" ixz="0" iyy="0.00124133333333" iyz="0" izz="0.002312"/>
    </inertial>
  </link>
  <joint name="left_leg_b_lf_joint" type="continuous">
    <origin rpy="0 0 0" xyz="0 0 -0.1065"/>
    <child link="lf"/>
    <parent link="left_leg_b"/>
    <axis rpy="0 0 0" xyz="0 1 0"/>
    <limit effort="100" velocity="100"/>
    <joint_properties damping="0.0" friction="0.0"/>
  </joint>
  <link name="rf">
    <collision name="rf_collision">
      <origin rpy="1.57079632679 0 0" xyz=" 0 0 0"/>
      <geometry>
        <cylinder length="0.032" radius="0.068"/>
      </geometry>
    </collision>
    <!--
      <visual name="${lr}_visual">
        <transparency>0.1</transparency>
        <origin xyz="${xyz}" rpy="${rpy}" />
        <geometry>
          <cylinder length="${wheelWidth - tY}" radius="${wheelRadius}"/>
        </geometry>

        <material name="green"/>
      </visual>
    -->
    <visual name="rf_visual_mesh">
      <origin rpy="1.57079632679 0 0" xyz=" 0 0 0"/>
      <geometry>
        <mesh filename="package://wheelchair_description/meshes/wheelchair_wheel_small.stl" scale="0.01 0.01 0.01"/>
      </geometry>
    </visual>
    <inertial name="rf_visual_intertial">
      <origin rpy="0 1.57079632679 1.57079632679" xyz="0 0 0"/>
      <mass value="1.0"/>
      <inertia ixx="0.00124133333333" ixy="0" ixz="0" iyy="0.00124133333333" iyz="0" izz="0.002312"/>
    </inertial>
  </link>
  <joint name="right_leg_b_rf_joint" type="continuous">
    <origin rpy="0 0 0" xyz="0 0 -0.1065"/>
    <child link="rf"/>
    <parent link="right_leg_b"/>
    <axis rpy="0 0 0" xyz="0 1 0"/>
    <limit effort="100" velocity="100"/>
    <joint_properties damping="0.0" friction="0.0"/>
  </joint>
</robot>
