<?xml version="1.0" encoding="utf-8"?>
<!-- =================================================================================== -->
<!-- |    This document was autogenerated by xacro from /home/kgoswam/wheelchair/src/wheelchair_description/urdf/wheelchair.xacro | -->
<!-- |    EDITING THIS FILE BY HAND IS NOT RECOMMENDED                                 | -->
<!-- =================================================================================== -->
<robot name="wheelchair" xmlns:xacro="http://www.ros.org/wiki/xacro">
  <!--gazebo>
    <plugin name="differential_drive_controller" filename="libgazebo_ros_diff_drive.so">
      <legacyMode>false</legacyMode>
      <alwaysOn>true</alwaysOn>
      <updateRate>20</updateRate>
      <leftJoint>axle_rear_left_wheel_joint</leftJoint>
      <rightJoint>axle_rear_right_wheel_joint</rightJoint>
      <wheelSeparation>${axle_length}</wheelSeparation>
      <wheelDiameter>${2*main_wheel_radius}</wheelDiameter>
      <torque>20</torque>
      <commandTopic>cmd_vel</commandTopic>
      <odometryTopic>odom</odometryTopic>
      <odometryFrame>odom</odometryFrame>
      <robotBaseFrame>footprint</robotBaseFrame>
    </plugin>
  </gazebo-->
  <gazebo reference="footprint">
    <material>Gazebo/Green</material>
  </gazebo>
  <gazebo reference="rear_right_wheel">
    <material>Gazebo/Blue</material>
  </gazebo>
  <gazebo reference="rear_left_wheel">
    <material>Gazebo/Blue</material>
  </gazebo>
  <gazebo reference="front_left_wheel">
    <material>Gazebo/Blue</material>
  </gazebo>
  <gazebo reference="front_right_wheel">
    <material>Gazebo/Blue</material>
  </gazebo>
  <material name="black">
    <color rgba="0.0 0.0 0.0 1.0"/>
  </material>
  <material name="blue">
    <color rgba="0.0 0.0 0.8 1.0"/>
  </material>
  <material name="green">
    <color rgba="0.0 0.8 0.0 1.0"/>
  </material>
  <material name="grey">
    <color rgba="0.2 0.2 0.2 1.0"/>
  </material>
  <material name="orange">
    <color rgba="1.0 0.423529411765 0.0392156862745 1.0"/>
  </material>
  <material name="brown">
    <color rgba="0.870588235294 0.811764705882 0.764705882353 1.0"/>
  </material>
  <material name="red">
    <color rgba="0.8 0.0 0.0 1.0"/>
  </material>
  <material name="white">
    <color rgba="1.0 1.0 1.0 1.0"/>
  </material>
  <!--
    <gazebo reference="${lr}_wheel">
      <mu1 value="1.0"/>
      <mu2 value="1.0"/>
      <kp  value="10000000.0" />
      <kd  value="1.0" />
      <fdir1 value="1 0 0"/>
      <material>Gazebo/Black</material>
    </gazebo>


    <joint name="${lr}_wheel_hinge" type="continuous">
      <parent link="chassis"/>
      <child link="${lr}_wheel"/>
    <origin xyz="${-wheelPos+chassisLength/2} ${tY*wheelWidth/2+tY*chassisWidth/2} ${wheelRadius}" rpy="0 0 0" />
      <axis xyz="0 1 0" rpy="0 0 0" />
      <limit effort="10000" velocity="10000"/>
      <joint_properties damping="0.0" friction="0.0"/>
    </joint>


    <transmission name="${lr}_trans">
      <type>transmission_interface/SimpleTransmission</type>
      <joint name="${lr}_wheel_hinge">
        <hardwareInterface>EffortJointInterface</hardwareInterface>
      </joint>
      <actuator name="${lr}Motor">
        <hardwareInterface>EffortJointInterface</hardwareInterface>
        <mechanicalReduction>10</mechanicalReduction>
      </actuator>
    </transmission>
  -->
  <gazebo>
    <plugin filename="libgazebo_ros_diff_drive.so" name="differential_drive_controller">
      <legacyMode>false</legacyMode>
      <alwaysOn>true</alwaysOn>
      <updateRate>40</updateRate>
      <leftJoint>chassis_rear_left_wheel_mdu_joint</leftJoint>
      <rightJoint>chassis_rear_right_wheel_mdu_joint</rightJoint>
      <wheelSeparation>0.15</wheelSeparation>
      <wheelDiameter>0.1651</wheelDiameter>
      <torque>40</torque>
      <commandTopic>cmd_vel</commandTopic>
      <odometryTopic>odom</odometryTopic>
      <odometryFrame>odom</odometryFrame>
      <robotBaseFrame>footprint_mdu</robotBaseFrame>
    </plugin>
  </gazebo>
  <gazebo reference="chassis">
    <material>Gazebo/Red</material>
  </gazebo>
  <gazebo reference="rear_right_wheel_mdu">
    <material>Gazebo/Black</material>
  </gazebo>
  <gazebo reference="rear_left_wheel_mdu">
    <material>Gazebo/Black</material>
  </gazebo>
  <link name="chassis">
    <inertial name="chassis_intertial">
      <origin rpy="0 0 0" xyz="0 0 0"/>
      <mass value="15.0"/>
      <inertia ixx="0.040625" ixy="0" ixz="0" iyy="0.025" iyz="0" izz="0.025"/>
    </inertial>
    <collision name="collision">
      <geometry>
        <box size="0.1 0.15 0.1"/>
      </geometry>
    </collision>
    <visual name="chassis_visual">
      <origin rpy="0 0 0" xyz="0 0 0"/>
      <geometry>
        <box size="0.1 0.15 0.1"/>
      </geometry>
    </visual>
    <collision name="caster_collision">
      <origin rpy=" 0 0 0" xyz="-0.008725 0 -0.041275"/>
      <geometry>
        <sphere radius="0.041275"/>
      </geometry>
      <surface>
        <friction>
          <ode>
            <mu>0.5</mu>
            <mu2>0.5</mu2>
            <slip1>1.0</slip1>
            <slip2>1.0</slip2>
          </ode>
        </friction>
      </surface>
    </collision>
    <visual name="caster_visual">
      <origin rpy=" 0 0 0" xyz="-0.008725 0 -0.041275"/>
      <geometry>
        <sphere radius="0.041275"/>
      </geometry>
    </visual>
  </link>
  <link name="rear_left_wheel_mdu">
    <collision name="rear_left_wheel_mdu_collision">
      <origin rpy="-1.57079632679 0 0" xyz=" 0 0 0"/>
      <geometry>
        <cylinder length="0.05" radius="0.08255"/>
      </geometry>
    </collision>
    <visual name="rear_left_wheel_mdu_visual">
      <transparency>0.1</transparency>
      <origin rpy="-1.57079632679 0 0" xyz=" 0 0 0"/>
      <geometry>
        <cylinder length="0.03" radius="0.08255"/>
      </geometry>
      <material name="green"/>
    </visual>
    <!--visual name="${lr}_visual_mesh">
        <origin xyz="${xyz}" rpy="${rpy}" />

        <geometry>
          <mesh filename="package://wheelchair_description/meshes/${meshFile}.stl" scale="0.01 0.01 0.01"/>
        </geometry>
      </visual-->
    <inertial name="rear_left_wheel_mdu_visual_intertial">
      <origin rpy="0 1.57079632679 1.57079632679" xyz="0 0 0"/>
      <mass value="2.0"/>
      <inertia ixx="0.00382391791667" ixy="0" ixz="0" iyy="0.00382391791667" iyz="0" izz="0.0068145025"/>
    </inertial>
    <!-- This block connects the wheel joint to an actuator (motor), which informs both
		simulation and visualization of the robot -->
    <!--transmission name="${lr}_wheel_trans">
		  <type>transmission_interface/SimpleTransmission</type>
		  <actuator name="${lr}_wheel_motor">
			<mechanicalReduction>1</mechanicalReduction>
		  </actuator>
		  <joint name="${lr}_motor_wheel_joint">
			<hardwareInterface>VelocityJointInterface</hardwareInterface>
		  </joint>
		</transmission-->
  </link>
  <joint name="chassis_rear_left_wheel_mdu_joint" type="continuous">
    <origin rpy="0 0 0" xyz="0.0 0.095 0"/>
    <child link="rear_left_wheel_mdu"/>
    <parent link="chassis"/>
    <axis rpy="0 0 0" xyz="0 1 0"/>
    <limit effort="100" velocity="100"/>
    <joint_properties damping="0.01" friction="0.5"/>
  </joint>
  <link name="rear_right_wheel_mdu">
    <collision name="rear_right_wheel_mdu_collision">
      <origin rpy="1.57079632679 0 0" xyz=" 0 0 0"/>
      <geometry>
        <cylinder length="0.05" radius="0.08255"/>
      </geometry>
    </collision>
    <visual name="rear_right_wheel_mdu_visual">
      <transparency>0.1</transparency>
      <origin rpy="1.57079632679 0 0" xyz=" 0 0 0"/>
      <geometry>
        <cylinder length="0.03" radius="0.08255"/>
      </geometry>
      <material name="green"/>
    </visual>
    <!--visual name="${lr}_visual_mesh">
        <origin xyz="${xyz}" rpy="${rpy}" />

        <geometry>
          <mesh filename="package://wheelchair_description/meshes/${meshFile}.stl" scale="0.01 0.01 0.01"/>
        </geometry>
      </visual-->
    <inertial name="rear_right_wheel_mdu_visual_intertial">
      <origin rpy="0 1.57079632679 1.57079632679" xyz="0 0 0"/>
      <mass value="2.0"/>
      <inertia ixx="0.00382391791667" ixy="0" ixz="0" iyy="0.00382391791667" iyz="0" izz="0.0068145025"/>
    </inertial>
    <!-- This block connects the wheel joint to an actuator (motor), which informs both
		simulation and visualization of the robot -->
    <!--transmission name="${lr}_wheel_trans">
		  <type>transmission_interface/SimpleTransmission</type>
		  <actuator name="${lr}_wheel_motor">
			<mechanicalReduction>1</mechanicalReduction>
		  </actuator>
		  <joint name="${lr}_motor_wheel_joint">
			<hardwareInterface>VelocityJointInterface</hardwareInterface>
		  </joint>
		</transmission-->
  </link>
  <joint name="chassis_rear_right_wheel_mdu_joint" type="continuous">
    <origin rpy="0 0 0" xyz="0.0 -0.095 0"/>
    <child link="rear_right_wheel_mdu"/>
    <parent link="chassis"/>
    <axis rpy="0 0 0" xyz="0 1 0"/>
    <limit effort="100" velocity="100"/>
    <joint_properties damping="0.01" friction="0.5"/>
  </joint>
  <!--wheel_mdu  lr="front_right_pipe" tY="0.001" xyz=" 0 0 0" rpy="0 ${pi/2} 0" wheelWidth="${0.01}" wheelRadius="${0.005}" wheelMass="${0.5}" meshFile="pipe"/>
  <wheel_mdu  lr="front_left_pipe" tY="0.001" xyz=" 0 0 0" rpy="0 ${pi/2} 0" wheelWidth="${0.01}" wheelRadius="${0.005}" wheelMass="${0.5}" meshFile="pipe"/-->
  <!--link_ name="front_left_link" xyz=" 0 0 0" rpy="0 ${3*pi/4} 0" m="${0.1}" length="${0.001}" width="${0.01}" height="${0.01}" />
  <link_joint parent='chassis' child='front_left_link' xyz="${chassis_length_mdu/2 } ${chassis_width__mdu/2 - 0.01} ${0.082 + 0.00280 - 0.0444}" rpy="0 0 0" type="fixed"/-->
  <link name="front_right_link">
    <collision name="front_right_link_link_collision">
      <geometry>
        <box size="0.001 0.01 0.01"/>
      </geometry>
    </collision>
    <visual name="front_right_link_visual">
      <origin rpy="0 0 0" xyz=" 0 0 0"/>
      <geometry>
        <box size="0.001 0.01 0.01"/>
      </geometry>
    </visual>
    <inertial name="front_right_link_intertial">
      <origin rpy="0 0 0" xyz=" 0 0 0"/>
      <mass value="0.1"/>
      <inertia ixx="1.66666666667e-06" ixy="0" ixz="0" iyy="8.41666666667e-07" iyz="0" izz="8.41666666667e-07"/>
    </inertial>
  </link>
  <joint name="chassis_front_right_link_joint" type="fixed">
    <origin rpy="0 0 0" xyz="0.05 -0.065 0.0404"/>
    <parent link="chassis"/>
    <child link="front_right_link"/>
  </joint>
  <!--link_joint parent='front_right_pipe' child='chassis' xyz="${-chassis_length_mdu/2 } ${chassis_width__mdu/2} ${0.082 + 0.00280 - 0.0444}" rpy="0 0 0" type="fixed"/>

  <link_joint parent='front_left_pipe' child='chassis' xyz="${-chassis_length_mdu/2 } ${-chassis_width__mdu/2} ${0.082 + 0.00280 - 0.0444}" rpy="0 0 0" type="fixed"/-->
  <link name="footprint">
    <pose rpy=" 0 0 0" xyz="1 0 0"/>
    <visual>
      <origin rpy=" 0 0 0" xyz="0 0 0"/>
      <geometry>
        <box size="0.001 0.001 0.001"/>
      </geometry>
    </visual>
    <visual>
      <origin rpy="0 0 -3.14" xyz="0 0 0"/>
      <geometry>
        <mesh filename="package://wheelchair_description/meshes/wheelchair_chasis.stl" scale="0.01 0.01 0.01"/>
      </geometry>
    </visual>
  </link>
  <link name="axle">
    <inertial>
      <origin rpy=" 0 0 0" xyz="0 0 0"/>
      <mass value="2.0"/>
      <inertia ixx="0.0271611884373" ixy="0" ixz="0" iyy="3.33333333333e-05" iyz="0" izz="3.33333333333e-05"/>
    </inertial>
    <collision name="collision">
      <origin rpy=" 0 0 0" xyz="0 0 0"/>
      <geometry>
        <box size="0.01 0.403568 0.01"/>
      </geometry>
    </collision>
    <visual>
      <origin rpy=" 0 0 0" xyz="0 0 0"/>
      <geometry>
        <box size="0.01 0.403568 0.01"/>
      </geometry>
    </visual>
  </link>
  <joint name="footprint_axle_joint" type="fixed">
    <origin rpy="0 0 0" xyz="0 0 0.201784"/>
    <parent link="footprint"/>
    <child link="axle"/>
  </joint>
  <link name="base">
    <collision name="base_chassis_collision">
      <geometry>
        <box size="0.250676 0.323568 0.01"/>
      </geometry>
    </collision>
    <visual name="base_visual">
      <origin rpy="0 0 0" xyz="0.125338 0 0"/>
      <geometry>
        <box size="0.250676 0.323568 0.01"/>
      </geometry>
    </visual>
    <inertial name="base_intertial">
      <origin rpy="0 0 0" xyz="0.125338 0 0"/>
      <mass value="3.0"/>
      <inertia ixx="0.026199062656" ixy="0" ixz="0" iyy="0.015734614244" iyz="0" izz="0.015734614244"/>
    </inertial>
  </link>
  <joint name="axle_base_joint" type="fixed">
    <origin rpy="0 0 0" xyz="0 0 0.1"/>
    <parent link="axle"/>
    <child link="base"/>
  </joint>
  <link name="front_left_leg">
    <collision name="front_left_leg_chassis_collision">
      <geometry>
        <box size="0.01 0.01 0.16"/>
      </geometry>
    </collision>
    <visual name="front_left_leg_visual">
      <origin rpy="0 0 0" xyz="0 0 -0.08"/>
      <geometry>
        <box size="0.01 0.01 0.16"/>
      </geometry>
    </visual>
    <inertial name="front_left_leg_intertial">
      <origin rpy="0 0 0" xyz="0 0 -0.08"/>
      <mass value="0.25"/>
      <inertia ixx="0.000535416666667" ixy="0" ixz="0" iyy="0.000535416666667" iyz="0" izz="0.000535416666667"/>
    </inertial>
  </link>
  <joint name="base_front_left_leg_joint" type="fixed">
    <origin rpy="0 0 0" xyz="0.250676 0.161784 0"/>
    <parent link="base"/>
    <child link="front_left_leg"/>
  </joint>
  <link name="rear_left_leg">
    <collision name="rear_left_leg_link_collision">
      <geometry>
        <box size="0.15 0.01 0.01"/>
      </geometry>
    </collision>
    <visual name="rear_left_leg_visual">
      <origin rpy="0 0 0" xyz=" -0.075 0 0"/>
      <geometry>
        <box size="0.15 0.01 0.01"/>
      </geometry>
    </visual>
    <inertial name="rear_left_leg_intertial">
      <origin rpy="0 0 0" xyz=" -0.075 0 0"/>
      <mass value="0.25"/>
      <inertia ixx="4.16666666667e-06" ixy="0" ixz="0" iyy="0.000470833333333" iyz="0" izz="0.000470833333333"/>
    </inertial>
  </link>
  <link name="rear_right_leg">
    <collision name="rear_right_leg_link_collision">
      <geometry>
        <box size="0.15 0.01 0.01"/>
      </geometry>
    </collision>
    <visual name="rear_right_leg_visual">
      <origin rpy="0 0 0" xyz=" -0.075 0 0"/>
      <geometry>
        <box size="0.15 0.01 0.01"/>
      </geometry>
    </visual>
    <inertial name="rear_right_leg_intertial">
      <origin rpy="0 0 0" xyz=" -0.075 0 0"/>
      <mass value="0.25"/>
      <inertia ixx="4.16666666667e-06" ixy="0" ixz="0" iyy="0.000470833333333" iyz="0" izz="0.000470833333333"/>
    </inertial>
  </link>
  <joint name="axle_rear_left_leg_joint" type="fixed">
    <origin rpy="0 -0.785398163397 0" xyz="0 0.061784 0"/>
    <parent link="axle"/>
    <child link="rear_left_leg"/>
  </joint>
  <joint name="axle_rear_right_leg_joint" type="fixed">
    <origin rpy="0 -0.785398163397 0" xyz="0 -0.061784 0"/>
    <parent link="axle"/>
    <child link="rear_right_leg"/>
  </joint>
  <link name="front_right_leg">
    <collision name="front_right_leg_chassis_collision">
      <geometry>
        <box size="0.01 0.01 0.16"/>
      </geometry>
    </collision>
    <visual name="front_right_leg_visual">
      <origin rpy="0 0 0" xyz="-0.08 -0.08 -0.08"/>
      <geometry>
        <box size="0.01 0.01 0.16"/>
      </geometry>
    </visual>
    <inertial name="front_right_leg_intertial">
      <origin rpy="0 0 0" xyz="-0.08 -0.08 -0.08"/>
      <mass value="0.25"/>
      <inertia ixx="0.000535416666667" ixy="0" ixz="0" iyy="0.000535416666667" iyz="0" izz="0.000535416666667"/>
    </inertial>
  </link>
  <joint name="base_front_right_leg_joint" type="fixed">
    <origin rpy="0 0 0" xyz="0.250676 -0.161784 0"/>
    <parent link="base"/>
    <child link="front_right_leg"/>
  </joint>
  <link name="front_left_leg_rev">
    <collision name="front_left_leg_rev_collision">
      <origin rpy="0 0 0" xyz=" 0 0 0"/>
      <geometry>
        <mesh filename="package://wheelchair_description/meshes/wheelchair_wheel_rev.stl" scale="0.01 0.01 0.01"/>
      </geometry>
    </collision>
    <!--visual name="${lr}_visual">
        <transparency>0.1</transparency>
        <origin xyz="${xyz}" rpy="${rpy}" />
        <geometry>
          <cylinder length="${wheelWidth - tY}" radius="${wheelRadius}"/>
        </geometry>

        <material name="green"/>
      </visual-->
    <visual name="front_left_leg_rev_visual_mesh">
      <origin rpy="0 0 0" xyz=" 0 0 0"/>
      <geometry>
        <mesh filename="package://wheelchair_description/meshes/wheelchair_wheel_rev.stl" scale="0.01 0.01 0.01"/>
      </geometry>
    </visual>
    <inertial name="front_left_leg_rev_visual_intertial">
      <origin rpy="0 1.57079632679 1.57079632679" xyz="0 0 0"/>
      <mass value="0.25"/>
      <inertia ixx="0.000214583333333" ixy="0" ixz="0" iyy="0.000214583333333" iyz="0" izz="1.25e-05"/>
    </inertial>
  </link>
  <joint name="front_left_leg_front_left_leg_rev_joint" type="continuous">
    <origin rpy="0 0 0" xyz="0 0 -0.16"/>
    <child link="front_left_leg_rev"/>
    <parent link="front_left_leg"/>
    <axis rpy="0 0 0" xyz="0 0 1"/>
    <limit effort="100" velocity="100"/>
    <joint_properties damping="0.01" friction="0.5"/>
  </joint>
  <link name="front_right_leg_rev">
    <collision name="front_right_leg_rev_collision">
      <origin rpy="0 0 0" xyz=" 0 0 0"/>
      <geometry>
        <mesh filename="package://wheelchair_description/meshes/wheelchair_wheel_rev.stl" scale="0.01 0.01 0.01"/>
      </geometry>
    </collision>
    <!--visual name="${lr}_visual">
        <transparency>0.1</transparency>
        <origin xyz="${xyz}" rpy="${rpy}" />
        <geometry>
          <cylinder length="${wheelWidth - tY}" radius="${wheelRadius}"/>
        </geometry>

        <material name="green"/>
      </visual-->
    <visual name="front_right_leg_rev_visual_mesh">
      <origin rpy="0 0 0" xyz=" 0 0 0"/>
      <geometry>
        <mesh filename="package://wheelchair_description/meshes/wheelchair_wheel_rev.stl" scale="0.01 0.01 0.01"/>
      </geometry>
    </visual>
    <inertial name="front_right_leg_rev_visual_intertial">
      <origin rpy="0 1.57079632679 1.57079632679" xyz="0 0 0"/>
      <mass value="0.25"/>
      <inertia ixx="0.000214583333333" ixy="0" ixz="0" iyy="0.000214583333333" iyz="0" izz="1.25e-05"/>
    </inertial>
  </link>
  <joint name="front_right_leg_front_right_leg_rev_joint" type="continuous">
    <origin rpy="0 0 0" xyz="0 0 -0.16"/>
    <child link="front_right_leg_rev"/>
    <parent link="front_right_leg"/>
    <axis rpy="0 0 0" xyz="0 0 1"/>
    <limit effort="100" velocity="100"/>
    <joint_properties damping="0.01" friction="0.5"/>
  </joint>
  <link name="rear_left_wheel">
    <collision name="rear_left_wheel_collision">
      <origin rpy="-1.57079632679 0 0" xyz=" 0 0 0"/>
      <geometry>
        <mesh filename="package://wheelchair_description/meshes/wheelchair_wheel.stl" scale="0.01 0.01 0.01"/>
      </geometry>
    </collision>
    <!--visual name="${lr}_visual">
        <transparency>0.1</transparency>
        <origin xyz="${xyz}" rpy="${rpy}" />
        <geometry>
          <cylinder length="${wheelWidth - tY}" radius="${wheelRadius}"/>
        </geometry>

        <material name="green"/>
      </visual-->
    <visual name="rear_left_wheel_visual_mesh">
      <origin rpy="-1.57079632679 0 0" xyz=" 0 0 0"/>
      <geometry>
        <mesh filename="package://wheelchair_description/meshes/wheelchair_wheel.stl" scale="0.01 0.01 0.01"/>
      </geometry>
    </visual>
    <inertial name="rear_left_wheel_visual_intertial">
      <origin rpy="0 1.57079632679 1.57079632679" xyz="0 0 0"/>
      <mass value="3.0"/>
      <inertia ixx="0.0308560024656" ixy="0" ixz="0" iyy="0.0308560024656" iyz="0" izz="0.061075173984"/>
    </inertial>
  </link>
  <joint name="axle_rear_left_wheel_joint" type="continuous">
    <origin rpy="0 0 0" xyz="0 0.201784 0"/>
    <child link="rear_left_wheel"/>
    <parent link="axle"/>
    <axis rpy="0 0 0" xyz="0 1 0"/>
    <limit effort="100" velocity="100"/>
    <joint_properties damping="0.01" friction="0.5"/>
  </joint>
  <link name="rear_right_wheel">
    <collision name="rear_right_wheel_collision">
      <origin rpy="1.57079632679 0 0" xyz=" 0 0 0"/>
      <geometry>
        <mesh filename="package://wheelchair_description/meshes/wheelchair_wheel.stl" scale="0.01 0.01 0.01"/>
      </geometry>
    </collision>
    <!--visual name="${lr}_visual">
        <transparency>0.1</transparency>
        <origin xyz="${xyz}" rpy="${rpy}" />
        <geometry>
          <cylinder length="${wheelWidth - tY}" radius="${wheelRadius}"/>
        </geometry>

        <material name="green"/>
      </visual-->
    <visual name="rear_right_wheel_visual_mesh">
      <origin rpy="1.57079632679 0 0" xyz=" 0 0 0"/>
      <geometry>
        <mesh filename="package://wheelchair_description/meshes/wheelchair_wheel.stl" scale="0.01 0.01 0.01"/>
      </geometry>
    </visual>
    <inertial name="rear_right_wheel_visual_intertial">
      <origin rpy="0 1.57079632679 1.57079632679" xyz="0 0 0"/>
      <mass value="3.0"/>
      <inertia ixx="0.0308560024656" ixy="0" ixz="0" iyy="0.0308560024656" iyz="0" izz="0.061075173984"/>
    </inertial>
  </link>
  <joint name="axle_rear_right_wheel_joint" type="continuous">
    <origin rpy="0 0 0" xyz="0 -0.201784 0"/>
    <child link="rear_right_wheel"/>
    <parent link="axle"/>
    <axis rpy="0 0 0" xyz="0 1 0"/>
    <limit effort="100" velocity="100"/>
    <joint_properties damping="0.01" friction="0.5"/>
  </joint>
  <link name="front_left_wheel">
    <collision name="front_left_wheel_collision">
      <origin rpy="1.57079632679 0 0" xyz=" 0 0 0"/>
      <geometry>
        <mesh filename="package://wheelchair_description/meshes/wheelchair_wheel_small.stl" scale="0.01 0.01 0.01"/>
      </geometry>
    </collision>
    <!--visual name="${lr}_visual">
        <transparency>0.1</transparency>
        <origin xyz="${xyz}" rpy="${rpy}" />
        <geometry>
          <cylinder length="${wheelWidth - tY}" radius="${wheelRadius}"/>
        </geometry>

        <material name="green"/>
      </visual-->
    <visual name="front_left_wheel_visual_mesh">
      <origin rpy="1.57079632679 0 0" xyz=" 0 0 0"/>
      <geometry>
        <mesh filename="package://wheelchair_description/meshes/wheelchair_wheel_small.stl" scale="0.01 0.01 0.01"/>
      </geometry>
    </visual>
    <inertial name="front_left_wheel_visual_intertial">
      <origin rpy="0 1.57079632679 1.57079632679" xyz="0 0 0"/>
      <mass value="1.5"/>
      <inertia ixx="0.001862" ixy="0" ixz="0" iyy="0.001862" iyz="0" izz="0.003468"/>
    </inertial>
  </link>
  <joint name="front_left_leg_rev_front_left_wheel_joint" type="continuous">
    <origin rpy="0 0 0" xyz="0.017 0 -0.07352"/>
    <child link="front_left_wheel"/>
    <parent link="front_left_leg_rev"/>
    <axis rpy="0 0 0" xyz="0 1 0"/>
    <limit effort="100" velocity="100"/>
    <joint_properties damping="0.01" friction="0.5"/>
  </joint>
  <link name="front_right_wheel">
    <collision name="front_right_wheel_collision">
      <origin rpy="1.57079632679 0 0" xyz=" 0 0 0"/>
      <geometry>
        <mesh filename="package://wheelchair_description/meshes/wheelchair_wheel_small.stl" scale="0.01 0.01 0.01"/>
      </geometry>
    </collision>
    <!--visual name="${lr}_visual">
        <transparency>0.1</transparency>
        <origin xyz="${xyz}" rpy="${rpy}" />
        <geometry>
          <cylinder length="${wheelWidth - tY}" radius="${wheelRadius}"/>
        </geometry>

        <material name="green"/>
      </visual-->
    <visual name="front_right_wheel_visual_mesh">
      <origin rpy="1.57079632679 0 0" xyz=" 0 0 0"/>
      <geometry>
        <mesh filename="package://wheelchair_description/meshes/wheelchair_wheel_small.stl" scale="0.01 0.01 0.01"/>
      </geometry>
    </visual>
    <inertial name="front_right_wheel_visual_intertial">
      <origin rpy="0 1.57079632679 1.57079632679" xyz="0 0 0"/>
      <mass value="1.5"/>
      <inertia ixx="0.001862" ixy="0" ixz="0" iyy="0.001862" iyz="0" izz="0.003468"/>
    </inertial>
  </link>
  <joint name="front_right_leg_rev_front_right_wheel_joint" type="continuous">
    <origin rpy="0 0 0" xyz="0.017 0 -0.07352"/>
    <child link="front_right_wheel"/>
    <parent link="front_right_leg_rev"/>
    <axis rpy="0 0 0" xyz="0 1 0"/>
    <limit effort="100" velocity="100"/>
    <joint_properties damping="0.01" friction="0.5"/>
  </joint>
  <link name="person_body">
    <collision name="person_body_collision">
      <geometry>
        <sphere radius="0.141784"/>
      </geometry>
      <surface>
        <friction>
          <ode>
            <mu>0.5</mu>
            <mu2>0.5</mu2>
            <slip1>0.0</slip1>
            <slip2>0.0</slip2>
          </ode>
        </friction>
      </surface>
    </collision>
    <visual name="person_body_visual">
      <origin rpy="0 0 0" xyz="0 0 0"/>
      <geometry>
        <sphere radius="0.141784"/>
      </geometry>
    </visual>
    <inertial name="person_body_intertial">
      <origin rpy="0 0 0" xyz="0 0 0"/>
      <mass value="1"/>
      <inertia ixx="0.0080410810624" ixy="0" ixz="0" iyy="0.0080410810624" iyz="0" izz="0.0080410810624"/>
    </inertial>
  </link>
  <joint name="base_person_body_joint" type="fixed">
    <origin rpy="0 0 0" xyz="0.141784 0 0.141784"/>
    <parent link="base"/>
    <child link="person_body"/>
  </joint>
  <link name="person_head">
    <collision name="person_head_collision">
      <geometry>
        <sphere radius="0.080892"/>
      </geometry>
      <surface>
        <friction>
          <ode>
            <mu>0.5</mu>
            <mu2>0.5</mu2>
            <slip1>0.0</slip1>
            <slip2>0.0</slip2>
          </ode>
        </friction>
      </surface>
    </collision>
    <visual name="person_head_visual">
      <origin rpy="0 0 0" xyz="0 0 0"/>
      <geometry>
        <sphere radius="0.080892"/>
      </geometry>
    </visual>
    <inertial name="person_head_intertial">
      <origin rpy="0 0 0" xyz="0 0 0"/>
      <mass value="5"/>
      <inertia ixx="0.013087031328" ixy="0" ixz="0" iyy="0.013087031328" iyz="0" izz="0.013087031328"/>
    </inertial>
  </link>
  <joint name="person_body_person_head_joint" type="fixed">
    <origin rpy="0 0 0" xyz="0 0 0.161784"/>
    <parent link="person_body"/>
    <child link="person_head"/>
  </joint>
  <link name="rear_right_pipe">
    <collision name="rear_right_pipe_collision">
      <origin rpy="0 0 0" xyz="0 0 0.03824"/>
      <geometry>
        <mesh filename="package://wheelchair_description/meshes/pipe1.stl" scale="0.01 0.01 0.01"/>
      </geometry>
    </collision>
    <!--visual name="${lr}_visual">
        <transparency>0.1</transparency>
        <origin xyz="${xyz}" rpy="${rpy}" />
        <geometry>
          <cylinder length="${wheelWidth - tY}" radius="${wheelRadius}"/>
        </geometry>

        <material name="green"/>
      </visual-->
    <visual name="rear_right_pipe_visual_mesh">
      <origin rpy="0 0 0" xyz="0 0 0.03824"/>
      <geometry>
        <mesh filename="package://wheelchair_description/meshes/pipe1.stl" scale="0.01 0.01 0.01"/>
      </geometry>
    </visual>
    <inertial name="rear_right_pipe_visual_intertial">
      <origin rpy="0 1.57079632679 1.57079632679" xyz="0 0 0"/>
      <mass value="0.5"/>
      <inertia ixx="0.000107291666667" ixy="0" ixz="0" iyy="0.000107291666667" iyz="0" izz="6.25e-06"/>
    </inertial>
  </link>
  <link name="rear_left_pipe">
    <collision name="rear_left_pipe_collision">
      <origin rpy="0 0 0" xyz="0 0 0.03824"/>
      <geometry>
        <mesh filename="package://wheelchair_description/meshes/pipe1.stl" scale="0.01 0.01 0.01"/>
      </geometry>
    </collision>
    <!--visual name="${lr}_visual">
        <transparency>0.1</transparency>
        <origin xyz="${xyz}" rpy="${rpy}" />
        <geometry>
          <cylinder length="${wheelWidth - tY}" radius="${wheelRadius}"/>
        </geometry>

        <material name="green"/>
      </visual-->
    <visual name="rear_left_pipe_visual_mesh">
      <origin rpy="0 0 0" xyz="0 0 0.03824"/>
      <geometry>
        <mesh filename="package://wheelchair_description/meshes/pipe1.stl" scale="0.01 0.01 0.01"/>
      </geometry>
    </visual>
    <inertial name="rear_left_pipe_visual_intertial">
      <origin rpy="0 1.57079632679 1.57079632679" xyz="0 0 0"/>
      <mass value="0.5"/>
      <inertia ixx="0.000107291666667" ixy="0" ixz="0" iyy="0.000107291666667" iyz="0" izz="6.25e-06"/>
    </inertial>
  </link>
  <joint name="rear_right_leg_rear_right_pipe_joint" type="fixed">
    <origin rpy="0 -0.785398163397 0" xyz="-0.15 0 0"/>
    <parent link="rear_right_leg"/>
    <child link="rear_right_pipe"/>
  </joint>
  <joint name="rear_left_leg_rear_left_pipe_joint" type="fixed">
    <origin rpy="0 -0.785398163397 0" xyz="-0.15 0 0"/>
    <parent link="rear_left_leg"/>
    <child link="rear_left_pipe"/>
  </joint>
  <joint name="rear_left_pipe_chassis_joint" type="fixed">
    <origin rpy="0 1.57079632679 0" xyz="-0.0132 -0.06 0.11"/>
    <parent link="rear_left_pipe"/>
    <child link="chassis"/>
  </joint>
  <joint name="rear_right_pipe_front_right_link_joint" type="fixed">
    <origin rpy="0 0 0" xyz="0 0 0"/>
    <parent link="rear_right_pipe"/>
    <child link="front_right_link"/>
  </joint>
  <!--link_joint parent="rear_left_pipe" child ="front_left_link" xyz="0 0 0" rpy="0 0 0" type="fixed"/-->
</robot>
