<?xml version="1.0" encoding="utf-8"?>
<!-- =================================================================================== -->
<!-- |    This document was autogenerated by xacro from ../src/wheelchair_description/urdf/wheelchair.xacro | -->
<!-- |    EDITING THIS FILE BY HAND IS NOT RECOMMENDED                                 | -->
<!-- =================================================================================== -->
<robot name="wheelchair" xmlns:xacro="http://www.ros.org/wiki/xacro">
  <gazebo>
    <plugin filename="libgazebo_ros_diff_drive.so" name="differential_drive_controller">
      <legacyMode>false</legacyMode>
      <alwaysOn>true</alwaysOn>
      <updateRate>20</updateRate>
      <leftJoint>axle_rear_left_wheel_joint</leftJoint>
      <rightJoint>axle_rear_right_wheel_joint</rightJoint>
      <wheelSeparation>0.403568</wheelSeparation>
      <wheelDiameter>0.403568</wheelDiameter>
      <torque>20</torque>
      <commandTopic>cmd_vel</commandTopic>
      <odometryTopic>odom</odometryTopic>
      <odometryFrame>odom</odometryFrame>
      <robotBaseFrame>footprint</robotBaseFrame>
    </plugin>
  </gazebo>
  <gazebo reference="footprint">
    <material>Gazebo/Green</material>
  </gazebo>
  <gazebo reference="rear_right_wheel">
    <material>Gazebo/Blue</material>
  </gazebo>
  <gazebo reference="rear_left_wheel">
    <material>Gazebo/Blue</material>
  </gazebo>
  <gazebo reference="front_left_wheel">
    <material>Gazebo/Blue</material>
  </gazebo>
  <gazebo reference="front_right_wheel">
    <material>Gazebo/Blue</material>
  </gazebo>
  <material name="black">
    <color rgba="0.0 0.0 0.0 1.0"/>
  </material>
  <material name="blue">
    <color rgba="0.0 0.0 0.8 1.0"/>
  </material>
  <material name="green">
    <color rgba="0.0 0.8 0.0 1.0"/>
  </material>
  <material name="grey">
    <color rgba="0.2 0.2 0.2 1.0"/>
  </material>
  <material name="orange">
    <color rgba="1.0 0.423529411765 0.0392156862745 1.0"/>
  </material>
  <material name="brown">
    <color rgba="0.870588235294 0.811764705882 0.764705882353 1.0"/>
  </material>
  <material name="red">
    <color rgba="0.8 0.0 0.0 1.0"/>
  </material>
  <material name="white">
    <color rgba="1.0 1.0 1.0 1.0"/>
  </material>
  <!--
    <gazebo reference="${lr}_wheel">
      <mu1 value="1.0"/>
      <mu2 value="1.0"/>
      <kp  value="10000000.0" />
      <kd  value="1.0" />
      <fdir1 value="1 0 0"/>
      <material>Gazebo/Black</material>
    </gazebo>


    <joint name="${lr}_wheel_hinge" type="continuous">
      <parent link="chassis"/>
      <child link="${lr}_wheel"/>
    <origin xyz="${-wheelPos+chassisLength/2} ${tY*wheelWidth/2+tY*chassisWidth/2} ${wheelRadius}" rpy="0 0 0" />
      <axis xyz="0 1 0" rpy="0 0 0" />
      <limit effort="10000" velocity="10000"/>
      <joint_properties damping="0.0" friction="0.0"/>
    </joint>


    <transmission name="${lr}_trans">
      <type>transmission_interface/SimpleTransmission</type>
      <joint name="${lr}_wheel_hinge">
        <hardwareInterface>EffortJointInterface</hardwareInterface>
      </joint>
      <actuator name="${lr}Motor">
        <hardwareInterface>EffortJointInterface</hardwareInterface>
        <mechanicalReduction>10</mechanicalReduction>
      </actuator>
    </transmission>
  -->
  <link name="footprint">
    <visual>
      <origin rpy=" 0 0 0" xyz="0 0 0"/>
      <geometry>
        <box size="0.001 0.001 0.001"/>
      </geometry>
    </visual>
    <visual>
      <origin rpy="0 0 -3.14" xyz="0 0 0"/>
      <geometry>
        <mesh filename="package://wheelchair_description/meshes/wheelchair_chasis.stl" scale="0.01 0.01 0.01"/>
      </geometry>
    </visual>
  </link>
  <link name="axle">
    <inertial>
      <origin rpy=" 0 0 0" xyz="0 0 0"/>
      <mass value="2.0"/>
      <inertia ixx="0.0271611884373" ixy="0" ixz="0" iyy="3.33333333333e-05" iyz="0" izz="3.33333333333e-05"/>
    </inertial>
    <collision name="collision">
      <origin rpy=" 0 0 0" xyz="0 0 0"/>
      <geometry>
        <box size="0.01 0.403568 0.01"/>
      </geometry>
    </collision>
    <visual>
      <origin rpy=" 0 0 0" xyz="0 0 0"/>
      <geometry>
        <box size="0.01 0.403568 0.01"/>
      </geometry>
    </visual>
  </link>
  <joint name="footprint_axle_joint" type="fixed">
    <origin rpy="0 0 0" xyz="0 0 0.201784"/>
    <parent link="footprint"/>
    <child link="axle"/>
  </joint>
  <link name="base">
    <collision name="base_chassis_collision">
      <geometry>
        <box size="0.250676 0.223568 0.01"/>
      </geometry>
    </collision>
    <visual name="base_visual">
      <origin rpy="0 0 0" xyz="0.125338 0 0"/>
      <geometry>
        <box size="0.250676 0.223568 0.01"/>
      </geometry>
    </visual>
    <inertial name="base_intertial">
      <origin rpy="0 0 0" xyz="0.125338 0 0"/>
      <mass value="73.0"/>
      <inertia ixx="0.304669457963" ixy="0" ixz="0" iyy="0.382875613271" iyz="0" izz="0.382875613271"/>
    </inertial>
  </link>
  <joint name="axle_base_joint" type="fixed">
    <origin rpy="0 0 0" xyz="0 0 0"/>
    <parent link="axle"/>
    <child link="base"/>
  </joint>
  <link name="front_left_leg">
    <collision name="front_left_leg_chassis_collision">
      <geometry>
        <box size="0.01 0.01 0.0354"/>
      </geometry>
    </collision>
    <visual name="front_left_leg_visual">
      <origin rpy="0 0 0" xyz="0 0 -0.0177"/>
      <geometry>
        <box size="0.01 0.01 0.0354"/>
      </geometry>
    </visual>
    <inertial name="front_left_leg_intertial">
      <origin rpy="0 0 0" xyz="0 0 -0.0177"/>
      <mass value="0.25"/>
      <inertia ixx="2.81908333333e-05" ixy="0" ixz="0" iyy="2.81908333333e-05" iyz="0" izz="2.81908333333e-05"/>
    </inertial>
  </link>
  <joint name="base_front_left_leg_joint" type="fixed">
    <origin rpy="0 0 0" xyz="0.250676 0.111784 0"/>
    <parent link="base"/>
    <child link="front_left_leg"/>
  </joint>
  <link name="front_right_leg">
    <collision name="front_right_leg_chassis_collision">
      <geometry>
        <box size="0.01 0.01 0.0354"/>
      </geometry>
    </collision>
    <visual name="front_right_leg_visual">
      <origin rpy="0 0 0" xyz="0 0 -0.0177"/>
      <geometry>
        <box size="0.01 0.01 0.0354"/>
      </geometry>
    </visual>
    <inertial name="front_right_leg_intertial">
      <origin rpy="0 0 0" xyz="0 0 -0.0177"/>
      <mass value="0.25"/>
      <inertia ixx="2.81908333333e-05" ixy="0" ixz="0" iyy="2.81908333333e-05" iyz="0" izz="2.81908333333e-05"/>
    </inertial>
  </link>
  <joint name="base_front_right_leg_joint" type="fixed">
    <origin rpy="0 0 0" xyz="0.250676 -0.111784 0"/>
    <parent link="base"/>
    <child link="front_right_leg"/>
  </joint>
  <link name="front_left_leg_rev">
    <collision name="front_left_leg_rev_collision">
      <origin rpy="0 0 0" xyz=" 0 0 0"/>
      <geometry>
        <cylinder length="0.0356884" radius="0.01"/>
      </geometry>
    </collision>
    <!--
      <visual name="${lr}_visual">
        <transparency>0.1</transparency>
        <origin xyz="${xyz}" rpy="${rpy}" />
        <geometry>
          <cylinder length="${wheelWidth - tY}" radius="${wheelRadius}"/>
        </geometry>

        <material name="green"/>
      </visual>
    -->
    <visual name="front_left_leg_rev_visual_mesh">
      <origin rpy="0 0 0" xyz=" 0 0 0"/>
      <geometry>
        <mesh filename="package://wheelchair_description/meshes/wheelchair_wheel_rev.stl" scale="0.01 0.01 0.01"/>
      </geometry>
    </visual>
    <inertial name="front_left_leg_rev_visual_intertial">
      <origin rpy="0 1.57079632679 1.57079632679" xyz="0 0 0"/>
      <mass value="0.25"/>
      <inertia ixx="3.27846228033e-05" ixy="0" ixz="0" iyy="3.27846228033e-05" iyz="0" izz="1.25e-05"/>
    </inertial>
  </link>
  <joint name="front_left_leg_front_left_leg_rev_joint" type="continuous">
    <origin rpy="0 0 0" xyz="0 0 -0.0354"/>
    <child link="front_left_leg_rev"/>
    <parent link="front_left_leg"/>
    <axis rpy="0 0 0" xyz="0 0 1"/>
    <limit effort="100" velocity="100"/>
    <joint_properties damping="0.01" friction="0.5"/>
  </joint>
  <link name="front_right_leg_rev">
    <collision name="front_right_leg_rev_collision">
      <origin rpy="0 0 0" xyz=" 0 0 0"/>
      <geometry>
        <cylinder length="0.0356884" radius="0.01"/>
      </geometry>
    </collision>
    <!--
      <visual name="${lr}_visual">
        <transparency>0.1</transparency>
        <origin xyz="${xyz}" rpy="${rpy}" />
        <geometry>
          <cylinder length="${wheelWidth - tY}" radius="${wheelRadius}"/>
        </geometry>

        <material name="green"/>
      </visual>
    -->
    <visual name="front_right_leg_rev_visual_mesh">
      <origin rpy="0 0 0" xyz=" 0 0 0"/>
      <geometry>
        <mesh filename="package://wheelchair_description/meshes/wheelchair_wheel_rev.stl" scale="0.01 0.01 0.01"/>
      </geometry>
    </visual>
    <inertial name="front_right_leg_rev_visual_intertial">
      <origin rpy="0 1.57079632679 1.57079632679" xyz="0 0 0"/>
      <mass value="0.25"/>
      <inertia ixx="3.27846228033e-05" ixy="0" ixz="0" iyy="3.27846228033e-05" iyz="0" izz="1.25e-05"/>
    </inertial>
  </link>
  <joint name="front_right_leg_front_right_leg_rev_joint" type="continuous">
    <origin rpy="0 0 0" xyz="0 0 -0.0354"/>
    <child link="front_right_leg_rev"/>
    <parent link="front_right_leg"/>
    <axis rpy="0 0 0" xyz="0 0 1"/>
    <limit effort="100" velocity="100"/>
    <joint_properties damping="0.01" friction="0.5"/>
  </joint>
  <link name="rear_left_wheel">
    <collision name="rear_left_wheel_collision">
      <origin rpy="-1.57079632679 0 0" xyz=" 0 0 0"/>
      <geometry>
        <cylinder length="0.0356884" radius="0.201784"/>
      </geometry>
    </collision>
    <!--
      <visual name="${lr}_visual">
        <transparency>0.1</transparency>
        <origin xyz="${xyz}" rpy="${rpy}" />
        <geometry>
          <cylinder length="${wheelWidth - tY}" radius="${wheelRadius}"/>
        </geometry>

        <material name="green"/>
      </visual>
    -->
    <visual name="rear_left_wheel_visual_mesh">
      <origin rpy="-1.57079632679 0 0" xyz=" 0 0 0"/>
      <geometry>
        <mesh filename="package://wheelchair_description/meshes/wheelchair_wheel.stl" scale="0.01 0.01 0.01"/>
      </geometry>
    </visual>
    <inertial name="rear_left_wheel_visual_intertial">
      <origin rpy="0 1.57079632679 1.57079632679" xyz="0 0 0"/>
      <mass value="3.0"/>
      <inertia ixx="0.0308560024656" ixy="0" ixz="0" iyy="0.0308560024656" iyz="0" izz="0.061075173984"/>
    </inertial>
  </link>
  <joint name="axle_rear_left_wheel_joint" type="continuous">
    <origin rpy="0 0 0" xyz="0 0.201784 0"/>
    <child link="rear_left_wheel"/>
    <parent link="axle"/>
    <axis rpy="0 0 0" xyz="0 1 0"/>
    <limit effort="100" velocity="100"/>
    <joint_properties damping="0.01" friction="0.5"/>
  </joint>
  <link name="rear_right_wheel">
    <collision name="rear_right_wheel_collision">
      <origin rpy="1.57079632679 0 0" xyz=" 0 0 0"/>
      <geometry>
        <cylinder length="0.0356884" radius="0.201784"/>
      </geometry>
    </collision>
    <!--
      <visual name="${lr}_visual">
        <transparency>0.1</transparency>
        <origin xyz="${xyz}" rpy="${rpy}" />
        <geometry>
          <cylinder length="${wheelWidth - tY}" radius="${wheelRadius}"/>
        </geometry>

        <material name="green"/>
      </visual>
    -->
    <visual name="rear_right_wheel_visual_mesh">
      <origin rpy="1.57079632679 0 0" xyz=" 0 0 0"/>
      <geometry>
        <mesh filename="package://wheelchair_description/meshes/wheelchair_wheel.stl" scale="0.01 0.01 0.01"/>
      </geometry>
    </visual>
    <inertial name="rear_right_wheel_visual_intertial">
      <origin rpy="0 1.57079632679 1.57079632679" xyz="0 0 0"/>
      <mass value="3.0"/>
      <inertia ixx="0.0308560024656" ixy="0" ixz="0" iyy="0.0308560024656" iyz="0" izz="0.061075173984"/>
    </inertial>
  </link>
  <joint name="axle_rear_right_wheel_joint" type="continuous">
    <origin rpy="0 0 0" xyz="0 -0.201784 0"/>
    <child link="rear_right_wheel"/>
    <parent link="axle"/>
    <axis rpy="0 0 0" xyz="0 1 0"/>
    <limit effort="100" velocity="100"/>
    <joint_properties damping="0.01" friction="0.5"/>
  </joint>
  <link name="front_left_wheel">
    <collision name="front_left_wheel_collision">
      <origin rpy="1.57079632679 0 0" xyz=" 0 0 0"/>
      <geometry>
        <cylinder length="0.032" radius="0.068"/>
      </geometry>
    </collision>
    <!--
      <visual name="${lr}_visual">
        <transparency>0.1</transparency>
        <origin xyz="${xyz}" rpy="${rpy}" />
        <geometry>
          <cylinder length="${wheelWidth - tY}" radius="${wheelRadius}"/>
        </geometry>

        <material name="green"/>
      </visual>
    -->
    <visual name="front_left_wheel_visual_mesh">
      <origin rpy="1.57079632679 0 0" xyz=" 0 0 0"/>
      <geometry>
        <mesh filename="package://wheelchair_description/meshes/wheelchair_wheel_small.stl" scale="0.01 0.01 0.01"/>
      </geometry>
    </visual>
    <inertial name="front_left_wheel_visual_intertial">
      <origin rpy="0 1.57079632679 1.57079632679" xyz="0 0 0"/>
      <mass value="1.5"/>
      <inertia ixx="0.001862" ixy="0" ixz="0" iyy="0.001862" iyz="0" izz="0.003468"/>
    </inertial>
  </link>
  <joint name="front_left_leg_rev_front_left_wheel_joint" type="continuous">
    <origin rpy="0 0 0" xyz="0.04 0 -0.096"/>
    <child link="front_left_wheel"/>
    <parent link="front_left_leg_rev"/>
    <axis rpy="0 0 0" xyz="0 1 0"/>
    <limit effort="100" velocity="100"/>
    <joint_properties damping="0.01" friction="0.5"/>
  </joint>
  <link name="front_right_wheel">
    <collision name="front_right_wheel_collision">
      <origin rpy="1.57079632679 0 0" xyz=" 0 0 0"/>
      <geometry>
        <cylinder length="0.032" radius="0.068"/>
      </geometry>
    </collision>
    <!--
      <visual name="${lr}_visual">
        <transparency>0.1</transparency>
        <origin xyz="${xyz}" rpy="${rpy}" />
        <geometry>
          <cylinder length="${wheelWidth - tY}" radius="${wheelRadius}"/>
        </geometry>

        <material name="green"/>
      </visual>
    -->
    <visual name="front_right_wheel_visual_mesh">
      <origin rpy="1.57079632679 0 0" xyz=" 0 0 0"/>
      <geometry>
        <mesh filename="package://wheelchair_description/meshes/wheelchair_wheel_small.stl" scale="0.01 0.01 0.01"/>
      </geometry>
    </visual>
    <inertial name="front_right_wheel_visual_intertial">
      <origin rpy="0 1.57079632679 1.57079632679" xyz="0 0 0"/>
      <mass value="1.5"/>
      <inertia ixx="0.001862" ixy="0" ixz="0" iyy="0.001862" iyz="0" izz="0.003468"/>
    </inertial>
  </link>
  <joint name="front_right_leg_rev_front_right_wheel_joint" type="continuous">
    <origin rpy="0 0 0" xyz="0.04 0 -0.096"/>
    <child link="front_right_wheel"/>
    <parent link="front_right_leg_rev"/>
    <axis rpy="0 0 0" xyz="0 1 0"/>
    <limit effort="100" velocity="100"/>
    <joint_properties damping="0.01" friction="0.5"/>
  </joint>
</robot>

